#VRML_SIM R2020a utf8
WorldInfo {
  basicTimeStep 16
}
Viewpoint {
  orientation -0.3212304002348888 -0.8988860965165744 -0.2980181461826257 1.7980965452829112
  position -1.0641890010718122 1.1843818830590107 -0.1716526792723841
}
TexturedBackground {
  texture "noon_cloudy_empty"
}
TexturedBackgroundLight {
  texture "noon_cloudy_empty"
  luminosity 2
}
Floor {
  size 1 1
}
DEF WALL_1 Solid {
  translation 0.5 0.05 0
  children [
    DEF WALL_SHAPE Shape {
      appearance PBRAppearance {
        baseColor 0.12549 0.368627 0.729412
        roughness 1
        metalness 0
      }
      geometry Box {
        size 0.02 0.1 0.98
      }
    }
  ]
  boundingObject USE WALL_SHAPE
}
DEF WALL_2 Solid {
  translation -0.5 0.05 0
  children [
    USE WALL_SHAPE
  ]
  name "solid(1)"
  boundingObject USE WALL_SHAPE
}
DEF WALL_3 Solid {
  translation 0 0.05 -0.5
  rotation 0 1 0 1.5708
  children [
    USE WALL_SHAPE
  ]
  name "solid(2)"
  boundingObject USE WALL_SHAPE
}
DEF WALL_4 Solid {
  translation 0 0.05 0.5
  rotation 0 1 0 1.5708
  children [
    USE WALL_SHAPE
  ]
  name "solid(3)"
  boundingObject USE WALL_SHAPE
}
Solid {
  translation 0.28 0.05 -0.33
  children [
    DEF Ball Shape {
      appearance PBRAppearance {
        baseColor 0.9 0.1 0
        roughness 1
        metalness 0
      }
      geometry Sphere {
        radius 0.06
        subdivision 2
      }
    }
  ]
  name "solid(4)"
  boundingObject USE Ball
  physics Physics {
    mass 3
  }
}
Solid {
  translation 0.28 0.07 -0.12
  children [
    DEF Ball Shape {
      appearance PBRAppearance {
        baseColor 0 0.2 0
        roughness 1
        metalness 0
      }
      geometry Sphere {
        radius 0.07
        subdivision 2
      }
    }
  ]
  name "solid(7)"
  boundingObject USE Ball
  physics Physics {
    mass 5
  }
}
Solid {
  translation 0.28 0.06 0.38
  children [
    DEF Ball Shape {
      appearance PBRAppearance {
        baseColor 0 1 0
        roughness 1
        metalness 0
      }
      geometry Sphere {
        radius 0.07
        subdivision 2
      }
    }
  ]
  name "solid(6)"
  boundingObject USE Ball
  physics Physics {
    mass 2
  }
}
Solid {
  translation 0.28 0.03 0.08
  children [
    DEF Ball Shape {
      appearance PBRAppearance {
        baseColor 0 0 0.9
        roughness 1
        metalness 0
      }
      geometry Sphere {
        radius 0.04
        subdivision 2
      }
    }
  ]
  name "solid(5)"
  boundingObject USE Ball
  physics Physics {
    mass 6
  }
}
DEF Ball Solid {
  translation -0.0379114 0.07 -0.219125
  children [
    Shape {
      appearance PBRAppearance {
        roughness 1
        metalness 0
      }
      geometry DEF BALL_GEOMETRY Sphere {
        radius 0.05
        subdivision 2
      }
    }
  ]
  name "solid(8)"
  boundingObject USE BALL_GEOMETRY
  physics Physics {
  }
}
Robot {
  translation 0.1 0.05 0.1
  rotation 0 -1 0 2.78858
  children [
    DEF BODY Shape {
      appearance PBRAppearance {
        baseColor 0 0.585845 0
        roughness 1
        metalness 0
      }
      geometry Box {
        size 0.1 0.05 0.2
      }
    }
    DEF WHEEL1 HingeJoint {
      jointParameters HingeJointParameters {
        anchor 0.06 0 0.05
      }
      device [
        RotationalMotor {
          name "wheel1"
        }
      ]
      endPoint Solid {
        translation 0.06 0 0.05
        rotation 0 0 1 1.5708
        children [
          DEF WHEEL Shape {
            appearance PBRAppearance {
              baseColor 0.8 0 0
              roughness 1
              metalness 0
            }
            geometry Cylinder {
              height 0.02
              radius 0.04
              subdivision 24
            }
          }
        ]
        boundingObject USE WHEEL
        physics Physics {
        }
      }
    }
    DEF WHEEL2 HingeJoint {
      jointParameters HingeJointParameters {
        anchor -0.06 0 0.05
      }
      device [
        RotationalMotor {
          name "wheel2"
        }
      ]
      endPoint Solid {
        translation -0.06 0 0.05
        rotation 0 0 1 1.5708
        children [
          USE WHEEL
        ]
        name "solid(1)"
        boundingObject USE WHEEL
        physics Physics {
        }
      }
    }
    DEF WHEEL3 HingeJoint {
      jointParameters HingeJointParameters {
        anchor 0.06 0 -0.05
      }
      device [
        RotationalMotor {
          name "wheel3"
        }
      ]
      endPoint Solid {
        translation 0.06 0 -0.05
        rotation 0 0 1 1.5708
        children [
          USE WHEEL
        ]
        name "solid(2)"
        boundingObject USE WHEEL
        physics Physics {
        }
      }
    }
    DEF WHEEL4 HingeJoint {
      jointParameters HingeJointParameters {
        anchor -0.06 0 -0.05
      }
      device [
        RotationalMotor {
          name "wheel4"
        }
      ]
      endPoint Solid {
        translation -0.06 0 -0.05
        rotation 0 0 1 1.5708
        children [
          USE WHEEL
        ]
        name "solid(3)"
        boundingObject USE WHEEL
        physics Physics {
        }
      }
    }
    DEF DS_RIGHT DistanceSensor {
      translation -0.03 0 0.1
      rotation 0 1 0 -1.87079
      children [
        Shape {
          appearance PBRAppearance {
            baseColor 0.8 0 0
            roughness 1
            metalness 0
          }
          geometry Box {
            size 0.01 0.01 0.01
          }
        }
      ]
      name "ds_right"
    }
    DEF DS_LEFT DistanceSensor {
      translation 0.03 0 0.1
      rotation 0 1 0 -1.27079
      children [
        Shape {
          appearance PBRAppearance {
            baseColor 0.8 0 0
            roughness 1
            metalness 0
          }
          geometry Box {
            size 0.01 0.01 0.01
          }
        }
      ]
      name "ds_left"
    }
  ]
  boundingObject USE BODY
  physics Physics {
    density -1
    mass 1
  }
  controller "rovio"
}
